Workbook

Sheet Resumo
A1: Preço por custos no lugar do markup — validação (09/10/2026)
A2: Matriz. Promocionais não mudam: servem de régua. Tudo recalcula a partir da aba Premissas.
A4: A regra (promocionais como régua)
A5: Promocionais que empatam ou ficam abaixo do preço por custos | B5: =Promocionais!F39 | C5: Tem que dar 33 de 33.
A6: Promocional mais barato que o preço por custos, em média | B6: =Promocionais!F40
A7: Menor folga (kit mais apertado) | B7: =Promocionais!F41 | C7: Perto de zero = esse kit empata.
A8: Elétrica fixa mínima para os 33 cumprirem | B8: =Promocionais!F42 | C8: Com o R$/kWp das Premissas.
A10: O que muda no catálogo da Matriz (587 kits Helte)
A11: Diferença média: preço por custos × preço de hoje | B11: =AVERAGE(Catalogo!Q5:Q591) | C11: Positivo = fica mais caro que hoje.
A12: Kits que ficam mais baratos que hoje | B12: =COUNTIF(Catalogo!P5:P591,"<0")
A13: Kits que ficam mais caros que hoje | B13: =COUNTIF(Catalogo!P5:P591,">0")
A14: Maior queda (%) | B14: =MIN(Catalogo!Q5:Q591)
A15: Maior alta (%) | B15: =MAX(Catalogo!Q5:Q591)
A17: Diferença média por marca de inversor
A18: CHINT | B18: =AVERAGEIFS(Catalogo!Q5:Q591,Catalogo!B5:B591,"CHINT") | C18: =COUNTIF(Catalogo!B5:B591,"CHINT")&" kits"
A19: FRONIUS | B19: =AVERAGEIFS(Catalogo!Q5:Q591,Catalogo!B5:B591,"FRONIUS") | C19: =COUNTIF(Catalogo!B5:B591,"FRONIUS")&" kits"
A20: GOODWE | B20: =AVERAGEIFS(Catalogo!Q5:Q591,Catalogo!B5:B591,"GOODWE") | C20: =COUNTIF(Catalogo!B5:B591,"GOODWE")&" kits"
A21: GROWATT | B21: =AVERAGEIFS(Catalogo!Q5:Q591,Catalogo!B5:B591,"GROWATT") | C21: =COUNTIF(Catalogo!B5:B591,"GROWATT")&" kits"
A22: HOYMILES | B22: =AVERAGEIFS(Catalogo!Q5:Q591,Catalogo!B5:B591,"HOYMILES") | C22: =COUNTIF(Catalogo!B5:B591,"HOYMILES")&" kits"
A23: SOFAR | B23: =AVERAGEIFS(Catalogo!Q5:Q591,Catalogo!B5:B591,"SOFAR") | C23: =COUNTIF(Catalogo!B5:B591,"SOFAR")&" kits"
A24: SOLIS | B24: =AVERAGEIFS(Catalogo!Q5:Q591,Catalogo!B5:B591,"SOLIS") | C24: =COUNTIF(Catalogo!B5:B591,"SOLIS")&" kits"
A26: Como o preço é calculado
A27: • Custos fixos da obra = instalação × módulos + ART + placas + projeto da Rede + elétrica fixa + elétrica × kWp
A28: • Preço por custos = (kit + custos fixos − imposto × kit) ÷ (1 − comissão − royalties − imposto − margem alvo)
A29: • "De" = preço + 13,38% (acima de R$ 30 mil, cresce pela raiz do preço) — mesma regra de hoje
A30: • Sem piso: a regra dos promocionais é cumprida pelos valores do centro de custo, não por ajuste no preço.
A31: • A plataforma arredonda cada linha em centavos; diferenças de 1 a 2 centavos com o Excel são esperadas.
A33: Abas
A34: Premissas | B34: Centro de custo da Matriz, markup, preços Helte e inversores. Tudo editável.
A35: Promocionais | B35: Os 33 promocionais: confere a regra "empata ou fica acima" e a elétrica mínima.
A36: Catalogo | B36: 587 kits: preço de hoje × preço por custos (com filtro). É o que o vendedor vai ver.
A37: Cotacao | B37: Cotação de distribuidora: markup × custos, com 3 cotações reais de 08/10.

Sheet Premissas
A1: Premissas — edite as células amarelas e a planilha recalcula
A2: Azul com fundo amarelo = editável. Verde = vem de outra aba. Preto = fórmula.
A4: Centro de custo da Matriz (o que a unidade preenche em Financeiro → Config)
A5: Imposto (% sobre venda − kit) | B5: 0.138 | C5: Cadastro atual da Matriz.
A6: Comissão (% sobre a venda) | B6: 0.08 | C6: Cadastro atual da Matriz.
A7: Royalties + fundo de publicidade (% sobre a venda) | B7: 0 | C7: Matriz não paga. Nas franquias vem da Rede.
A8: Instalação (R$ por módulo) | B8: 70 | C8: Decisão do usuário: instaladores cobram por módulo.
A9: ART (R$ por venda) | B9: 110 | C9: À parte do projeto da Rede (decisão de 09/10).
A10: Placas de advertência (R$ por venda) | B10: 30 | C10: Cadastro atual da Matriz.
A11: Projeto da Rede (R$ por venda) | B11: 0 | C11: Matriz não paga. Nas franquias vem da tabela por kWp (Rede → Unidades).
A12: Elétrica fixa por obra (R$ por venda) | B12: 345 | C12: ESTIMATIVA (engenharia reversa): quadro, disjuntores, DPS. Troque pelo valor real.
A13: Elétrica que cresce com o sistema (R$ por kWp) | B13: 118.5 | C13: ESTIMATIVA (engenharia reversa). Troque pelo valor real.
A14: Margem alvo | B14: 0.22 | C14: Cadastro atual da Matriz.
A16: Markup atual (para comparar)
A17: Relação inversor | B17: 1.7717293 | C17: Planilha de 30/09: preço = custo × relação ÷ fator, final 97, × fator.
A18: Fator inversor | B18: 1.05
A19: Relação micro | B19: 1.7498326 | C19: Planilha de 06/10 (tarde).
A20: Fator micro | B20: 1.071
A21: "De": acréscimo sobre o preço | B21: 0.1337539 | C21: Acima de R$ 30 mil cresce pela raiz do preço (igual à plataforma).
A23: Preços Helte (06/10; cabo atualizado em 08/10)
A24: Módulo RONMA 620W (R$) | B24: 548
A25: Potência do módulo (kW) | B25: 0.62
A26: Perfil 2,40 m (R$) | B26: 44.64
A27: Fixação cerâmico 4 módulos (R$) | B27: 135.65
A28: Fixação cerâmico 2 módulos (R$) | B28: 72.72
A29: Cabo 4 mm (R$/m por cor) | B29: 4.25 | C29: Baixou de 5,87 em 08/10.
A30: Par de conectores (R$) | B30: 12
A31: Microinversor Hoymiles 2,25 kW (R$) | B31: 942.49 | C31: 1 a cada 4 módulos; 4 pares de conector cada.
A32: Fixação do micro (R$) | B32: 9
A33: Frete mínimo (R$) | B33: 400 | C33: Regra conferida em 64 cotações (erro até R$ 0,07).
A34: Frete % (peças abaixo do limite) | B34: 0.038494
A35: Frete % (peças a partir do limite) | B35: 0.031394
A36: Limite das peças para o frete (R$) | B36: 25000
A38: Inversores na Helte (preço e pares de conector — cotações de 06/10 e 08/10)
A39: Inversor | B39: Preço (R$) | C39: Pares de conector
A40: SOFAR 3300TL-G3 | B40: 1399 | C40: 1
A41: SOFAR 5KTLM-G3 | B41: 1590 | C41: 2
A42: SOFAR 6KTLM-G3 | B42: 1690 | C42: 2
A43: SOFAR 7,5K | B43: 2600 | C43: 2
A44: SOFAR 10KTLM-G3 | B44: 3000 | C44: 3
...

Sheet Promocionais
A1: Régua: os 33 promocionais têm que empatar ou ficar mais baratos que o preço por custos
A2: Os promocionais não mudam de preço. Aqui só se confere a regra com as premissas atuais.
A4: Tipo | B4: Módulos | C4: kWp | D4: Inversor | E4: Qtd inversores | F4: Promocional (Matriz) | G4: Peças (R$) | H4: Frete (R$) | I4: Custo do kit c/ frete | J4: Custos fixos da obra | K4: Preço por custos | L4: Preço por custos − promocional | M4: Promocional mais barato em % | N4: Regra ok? | O4: Margem no promocional | P4: Elétrica fixa mínima p/ empatar | Q4: Plataforma (JS): preço por custos | R4: Excel − plataforma
A5: Inversor | B5: 5 | C5: =B5*Premissas!$B$25 | D5: SOFAR 3300TL-G3 | E5: 1 | F5: 9236.85 | G5: =(B5*Premissas!$B$24+(2*ROUNDUP(B5/2,0))*Premissas!$B$26+INT((2*ROUNDUP(B5/2,0))/4)*Premissas!$B$27+MOD((2*ROUNDUP(B5/2,0)),4)/2*Premissas!$B$28+2*IF(B5<=19,3*B5,IF(B5<=50,ROUNDUP(2.5*B5,0),2*B5))*Premissas!$B$29+IF(A5="Micro",E5*(Premissas!$B$31+Premissas!$B$32+4*Premissas!$B$30),E5*(INDEX(Premissas!$B$40:$B$71,MATCH(D5,Premissas!$A$40:$A$71,0))+INDEX(Premissas!$C$40:$C$71,MATCH(D5,Premissas!$A$40:$A$71,0))*Premissas!$B$30))) | H5: =IF(G5<Premissas!$B$36,MAX(Premissas!$B$33,G5*Premissas!$B$34),G5*Premissas!$B$35) | I5: =ROUND(G5+H5,2) | J5: =B5*Premissas!$B$8+Premissas!$B$9+Premissas!$B$10+Premissas!$B$11+Premissas!$B$12+ROUND(Premissas!$B$13*C5,2) | K5: =ROUNDUP((I5+J5-Premissas!$B$5*I5)/(1-Premissas!$B$6-Premissas!$B$7-Premissas!$B$5-Premissas!$B$14),2) | L5: =K5-F5 | M5: =L5/K5 | N5: =IF(K5>=F5,"Sim","NÃO") | O5: =(F5-I5-Premissas!$B$5*(F5-I5)-(Premissas!$B$6+Premissas!$B$7)*F5-J5)/F5 | P5: =F5*(1-Premissas!$B$6-Premissas!$B$7-Premissas!$B$5-Premissas!$B$14)-I5*(1-Premissas!$B$5)-(J5-Premissas!$B$12) | Q5: 10045.75 | R5: =K5-Q5
A6: Inversor | B6: 6 | C6: =B6*Premissas!$B$25 | D6: SOFAR 3300TL-G3 | E6: 1 | F6: 10286.85 | G6: =(B6*Premissas!$B$24+(2*ROUNDUP(B6/2,0))*Premissas!$B$26+INT((2*ROUNDUP(B6/2,0))/4)*Premissas!$B$27+MOD((2*ROUNDUP(B6/2,0)),4)/2*Premissas!$B$28+2*IF(B6<=19,3*B6,IF(B6<=50,ROUNDUP(2.5*B6,0),2*B6))*Premissas!$B$29+IF(A6="Micro",E6*(Premissas!$B$31+Premissas!$B$32+4*Premissas!$B$30),E6*(INDEX(Premissas!$B$40:$B$71,MATCH(D6,Premissas!$A$40:$A$71,0))+INDEX(Premissas!$C$40:$C$71,MATCH(D6,Premissas!$A$40:$A$71,0))*Premissas!$B$30))) | H6: =IF(G6<Premissas!$B$36,MAX(Premissas!$B$33,G6*Premissas!$B$34),G6*Premissas!$B$35) | I6: =ROUND(G6+H6,2) | J6: =B6*Premissas!$B$8+Premissas!$B$9+Premissas!$B$10+Premissas!$B$11+Premissas!$B$12+ROUND(Premissas!$B$13*C6,2) | K6: =ROUNDUP((I6+J6-Premissas!$B$5*I6)/(1-Premissas!$B$6-Premissas!$B$7-Premissas!$B$5-Premissas!$B$14),2) | L6: =K6-F6 | M6: =L6/K6 | N6: =IF(K6>=F6,"Sim","NÃO") | O6: =(F6-I6-Premissas!$B$5*(F6-I6)-(Premissas!$B$6+Premissas!$B$7)*F6-J6)/F6 | P6: =F6*(1-Premissas!$B$6-Premissas!$B$7-Premissas!$B$5-Premissas!$B$14)-I6*(1-Premissas!$B$5)-(J6-Premissas!$B$12) | Q6: 11180.68 | R6: =K6-Q6
A7: Inversor | B7: 7 | C7: =B7*Premissas!$B$25 | D7: SOFAR 3300TL-G3 | E7: 1 | F7: 11651.85 | G7: =(B7*Premissas!$B$24+(2*ROUNDUP(B7/2,0))*Premissas!$B$26+INT((2*ROUNDUP(B7/2,0))/4)*Premissas!$B$27+MOD((2*ROUNDUP(B7/2,0)),4)/2*Premissas!$B$28+2*IF(B7<=19,3*B7,IF(B7<=50,ROUNDUP(2.5*B7,0),2*B7))*Premissas!$B$29+IF(A7="Micro",E7*(Premissas!$B$31+Premissas!$B$32+4*Premissas!$B$30),E7*(INDEX(Premissas!$B$40:$B$71,MATCH(D7,Premissas!$A$40:$A$71,0))+INDEX(Premissas!$C$40:$C$71,MATCH(D7,Premissas!$A$40:$A$71,0))*Premissas!$B$30))) | H7: =IF(G7<Premissas!$B$36,MAX(Premissas!$B$33,G7*Premissas!$B$34),G7*Premissas!$B$35) | I7: =ROUND(G7+H7,2) | J7: =B7*Premissas!$B$8+Premissas!$B$9+Premissas!$B$10+Premissas!$B$11+Premissas!$B$12+ROUND(Premissas!$B$13*C7,2) | K7: =ROUNDUP((I7+J7-Premissas!$B$5*I7)/(1-Premissas!$B$6-Premissas!$B$7-Premissas!$B$5-Premissas!$B$14),2) | L7: =K7-F7 | M7: =L7/K7 | N7: =IF(K7>=F7,"Sim","NÃO") | O7: =(F7-I7-Premissas!$B$5*(F7-I7)-(Premissas!$B$6+Premissas!$B$7)*F7-J7)/F7 | P7: =F7*(1-Premissas!$B$6-Premissas!$B$7-Premissas!$B$5-Premissas!$B$14)-I7*(1-Premissas!$B$5)-(J7-Premissas!$B$12) | Q7: 12549.06 | R7: =K7-Q7
A8: Inversor | B8: 8 | C8: =B8*Premissas!$B$25 | D8: SOFAR 3300TL-G3 | E8: 1 | F8: 13016.85 | G8: =(B8*Premissas!$B$24+(2*ROUNDUP(B8/2,0))*Premissas!$B$26+INT((2*ROUNDUP(B8/2,0))/4)*Premissas!$B$27+MOD((2*ROUNDUP(B8/2,0)),4)/2*Premissas!$B$28+2*IF(B8<=19,3*B8,IF(B8<=50,ROUNDUP(2.5*B8,0),2*B8))*Premissas!$B$29+IF(A8="Micro",E8*(Premissas!$B$31+Premissas!$B$32+4*Premissas!$B$30),E8*(INDEX(Premissas!$B$40:$B$71,MATCH(D8,Premissas!$A$40:$A$71,0))+INDEX(Premissas!$C$40:$C$71,MATCH(D8,Premissas!$A$40:$A$71,0))*Premissas!$B$30))) | H8: =IF(G8<Premissas!$B$36,MAX(Premissas!$B$33,G8*Premissas!$B$34),G8*Premissas!$B$35) | I8: =ROUND(G8+H8,2) | J8: =B8*Premissas!$B$8+Premissas!$B$9+Premissas!$B$10+Premissas!$B$11+Premissas!$B$12+ROUND(Premissas!$B$13*C8,2) | K8: =ROUNDUP((I8+J8-Premissas!$B$5*I8)/(1-Premissas!$B$6-Premissas!$B$7-Premissas!$B$5-Premissas!$B$14),2) | L8: =K8-F8 | M8: =L8/K8 | N8: =IF(K8>=F8,"Sim","NÃO") | O8: =(F8-I8-Premissas!$B$5*(F8-I8)-(Premissas!$B$6+Premissas!$B$7)*F8-J8)/F8 | P8: =F8*(1-Premissas!$B$6-Premissas!$B$7-Premissas!$B$5-Premissas!$B$14)-I8*(1-Premissas!$B$5)-(J8-Premissas!$B$12) | Q8: 13683.99 | R8: =K8-Q8
A9: Inversor | B9: 9 | C9: =B9*Premissas!$B$25 | D9: SOFAR 5KTLM-G3 | E9: 1 | F9: 14276.85 | G9: =(B9*Premissas!$B$24+(2*ROUNDUP(B9/2,0))*Premissas!$B$26+INT((2*ROUNDUP(B9/2,0))/4)*Premissas!$B$27+MOD((2*ROUNDUP(B9/2,0)),4)/2*Premissas!$B$28+2*IF(B9<=19,3*B9,IF(B9<=50,ROUNDUP(2.5*B9,0),2*B9))*Premissas!$B$29+IF(A9="Micro",E9*(Premissas!$B$31+Premissas!$B$32+4*Premissas!$B$30),E9*(INDEX(Premissas!$B$40:$B$71,MATCH(D9,Premissas!$A$40:$A$71,0))+INDEX(Premissas!$C$40:$C$71,MATCH(D9,Premissas!$A$40:$A$71,0))*Premissas!$B$30))) | H9: =IF(G9<Premissas!$B$36,MAX(Premissas!$B$33,G9*Premissas!$B$34),G9*Premissas!$B$35) | I9: =ROUND(G9+H9,2) | J9: =B9*Premissas!$B$8+Premissas!$B$9+Premissas!$B$10+Premissas!$B$11+Premissas!$B$12+ROUND(Premissas!$B$13*C9,2) | K9: =ROUNDUP((I9+J9-Premissas!$B$5*I9)/(1-Premissas!$B$6-Premissas!$B$7-Premissas!$B$5-Premissas!$B$14),2) | L9: =K9-F9 | M9: =L9/K9 | N9: =IF(K9>=F9,"Sim","NÃO") | O9: =(F9-I9-Premissas!$B$5*(F9-I9)-(Premissas!$B$6+Premissas!$B$7)*F9-J9)/F9 | P9: =F9*(1-Premissas!$B$6-Premissas!$B$7-Premissas!$B$5-Premissas!$B$14)-I9*(1-Premissas!$B$5)-(J9-Premissas!$B$12) | Q9: 15378.75 | R9: =K9-Q9
A10: Inversor | B10: 10 | C10: =B10*Premissas!$B$25 | D10: SOFAR 5KTLM-G3 | E10: 1 | F10: 15326.85 | G10: =(B10*Premissas!$B$24+(2*ROUNDUP(B10/2,0))*Premissas!$B$26+INT((2*ROUNDUP(B10/2,0))/4)*Premissas!$B$27+MOD((2*ROUNDUP(B10/2,0)),4)/2*Premissas!$B$28+2*IF(B10<=19,3*B10,IF(B10<=50,ROUNDUP(2.5*B10,0),2*B10))*Premissas!$B$29+IF(A10="Micro",E10*(Premissas!$B$31+Premissas!$B$32+4*Premissas!$B$30),E10*(INDEX(Premissas!$B$40:$B$71,MATCH(D10,Premissas!$A$40:$A$71,0))+INDEX(Premissas!$C$40:$C$71,MATCH(D10,Premissas!$A$40:$A$71,0))*Premissas!$B$30))) | H10: =IF(G10<Premissas!$B$36,MAX(Premissas!$B$33,G10*Premissas!$B$34),G10*Premissas!$B$35) | I10: =ROUND(G10+H10,2) | J10: =B10*Premissas!$B$8+Premissas!$B$9+Premissas!$B$10+Premissas!$B$11+Premissas!$B$12+ROUND(Premissas!$B$13*C10,2) | K10: =ROUNDUP((I10+J10-Premissas!$B$5*I10)/(1-Premissas!$B$6-Premissas!$B$7-Premissas!$B$5-Premissas!$B$14),2) | L10: =K10-F10 | M10: =L10/K10 | N10: =IF(K10>=F10,"Sim","NÃO") | O10: =(F10-I10-Premissas!$B$5*(F10-I10)-(Premissas!$B$6+Premissas!$B$7)*F10-J10)/F10 | P10: =F10*(1-Premissas!$B$6-Premissas!$B$7-Premissas!$B$5-Premissas!$B$14)-I10*(1-Premissas!$B$5)-(J10-Premissas!$B$12) | Q10: 16513.67 | R10: =K10-Q10
A11: Inversor | B11: 11 | C11: =B11*Premissas!$B$25 | D11: SOFAR 5KTLM-G3 | E11: 1 | F11: 16691.85 | G11: =(B11*Premissas!$B$24+(2*ROUNDUP(B11/2,0))*Premissas!$B$26+INT((2*ROUNDUP(B11/2,0))/4)*Premissas!$B$27+MOD((2*ROUNDUP(B11/2,0)),4)/2*Premissas!$B$28+2*IF(B11<=19,3*B11,IF(B11<=50,ROUNDUP(2.5*B11,0),2*B11))*Premissas!$B$29+IF(A11="Micro",E11*(Premissas!$B$31+Premissas!$B$32+4*Premissas!$B$30),E11*(INDEX(Premissas!$B$40:$B$71,MATCH(D11,Premissas!$A$40:$A$71,0))+INDEX(Premissas!$C$40:$C$71,MATCH(D11,Premissas!$A$40:$A$71,0))*Premissas!$B$30))) | H11: =IF(G11<Premissas!$B$36,MAX(Premissas!$B$33,G11*Premissas!$B$34),G11*Premissas!$B$35) | I11: =ROUND(G11+H11,2) | J11: =B11*Premissas!$B$8+Premissas!$B$9+Premissas!$B$10+Premissas!$B$11+Premissas!$B$12+ROUND(Premissas!$B$13*C11,2) | K11: =ROUNDUP((I11+J11-Premissas!$B$5*I11)/(1-Premissas!$B$6-Premissas!$B$7-Premissas!$B$5-Premissas!$B$14),2) | L11: =K11-F11 | M11: =L11/K11 | N11: =IF(K11>=F11,"Sim","NÃO") | O11: =(F11-I11-Premissas!$B$5*(F11-I11)-(Premissas!$B$6+Premissas!$B$7)*F11-J11)/F11 | P11: =F11*(1-Premissas!$B$6-Premissas!$B$7-Premissas!$B$5-Premissas!$B$14)-I11*(1-Premissas!$B$5)-(J11-Premissas!$B$12) | Q11: 17882.05 | R11: =K11-Q11
A12: Inversor | B12: 12 | C12: =B12*Premissas!$B$25 | D12: SOFAR 5KTLM-G3 | E12: 1 | F12: 17741.85 | G12: =(B12*Premissas!$B$24+(2*ROUNDUP(B12/2,0))*Premissas!$B$26+INT((2*ROUNDUP(B12/2,0))/4)*Premissas!$B$27+MOD((2*ROUNDUP(B12/2,0)),4)/2*Premissas!$B$28+2*IF(B12<=19,3*B12,IF(B12<=50,ROUNDUP(2.5*B12,0),2*B12))*Premissas!$B$29+IF(A12="Micro",E12*(Premissas!$B$31+Premissas!$B$32+4*Premissas!$B$30),E12*(INDEX(Premissas!$B$40:$B$71,MATCH(D12,Premissas!$A$40:$A$71,0))+INDEX(Premissas!$C$40:$C$71,MATCH(D12,Premissas!$A$40:$A$71,0))*Premissas!$B$30))) | H12: =IF(G12<Premissas!$B$36,MAX(Premissas!$B$33,G12*Premissas!$B$34),G12*Premissas!$B$35) | I12: =ROUND(G12+H12,2) | J12: =B12*Premissas!$B$8+Premissas!$B$9+Premissas!$B$10+Premissas!$B$11+Premissas!$B$12+ROUND(Premissas!$B$13*C12,2) | K12: =ROUNDUP((I12+J12-Premissas!$B$5*I12)/(1-Premissas!$B$6-Premissas!$B$7-Premissas!$B$5-Premissas!$B$14),2) | L12: =K12-F12 | M12: =L12/K12 | N12: =IF(K12>=F12,"Sim","NÃO") | O12: =(F12-I12-Premissas!$B$5*(F12-I12)-(Premissas!$B$6+Premissas!$B$7)*F12-J12)/F12 | P12: =F12*(1-Premissas!$B$6-Premissas!$B$7-Premissas!$B$5-Premissas!$B$14)-I12*(1-Premissas!$B$5)-(J12-Premissas!$B$12) | Q12: 19016.98 | R12: =K12-Q12
A13: Inversor | B13: 13 | C13: =B13*Premissas!$B$25 | D13: SOFAR 6KTLM-G3 | E13: 1 | F13: 19001.85 | G13: =(B13*Premissas!$B$24+(2*ROUNDUP(B13/2,0))*Premissas!$B$26+INT((2*ROUNDUP(B13/2,0))/4)*Premissas!$B$27+MOD((2*ROUNDUP(B13/2,0)),4)/2*Premissas!$B$28+2*IF(B13<=19,3*B13,IF(B13<=50,ROUNDUP(2.5*B13,0),2*B13))*Premissas!$B$29+IF(A13="Micro",E13*(Premissas!$B$31+Premissas!$B$32+4*Premissas!$B$30),E13*(INDEX(Premissas!$B$40:$B$71,MATCH(D13,Premissas!$A$40:$A$71,0))+INDEX(Premissas!$C$40:$C$71,MATCH(D13,Premissas!$A$40:$A$71,0))*Premissas!$B$30))) | H13: =IF(G13<Premissas!$B$36,MAX(Premissas!$B$33,G13*Premissas!$B$34),G13*Premissas!$B$35) | I13: =ROUND(G13+H13,2) | J13: =B13*Premissas!$B$8+Premissas!$B$9+Premissas!$B$10+Premissas!$B$11+Premissas!$B$12+ROUND(Premissas!$B$13*C13,2) | K13: =ROUNDUP((I13+J13-Premissas!$B$5*I13)/(1-Premissas!$B$6-Premissas!$B$7-Premissas!$B$5-Premissas!$B$14),2) | L13: =K13-F13 | M13: =L13/K13 | N13: =IF(K13>=F13,"Sim","NÃO") | O13: =(F13-I13-Premissas!$B$5*(F13-I13)-(Premissas!$B$6+Premissas!$B$7)*F13-J13)/F13 | P13: =F13*(1-Premissas!$B$6-Premissas!$B$7-Premissas!$B$5-Premissas!$B$14)-I13*(1-Premissas!$B$5)-(J13-Premissas!$B$12) | Q13: 20553.76 | R13: =K13-Q13
A14: Inversor | B14: 14 | C14: =B14*Premissas!$B$25 | D14: SOFAR 6KTLM-G3 | E14: 1 | F14: 20261.85 | G14: =(B14*Premissas!$B$24+(2*ROUNDUP(B14/2,0))*Premissas!$B$26+INT((2*ROUNDUP(B14/2,0))/4)*Premissas!$B$27+MOD((2*ROUNDUP(B14/2,0)),4)/2*Premissas!$B$28+2*IF(B14<=19,3*B14,IF(B14<=50,ROUNDUP(2.5*B14,0),2*B14))*Premissas!$B$29+IF(A14="Micro",E14*(Premissas!$B$31+Premissas!$B$32+4*Premissas!$B$30),E14*(INDEX(Premissas!$B$40:$B$71,MATCH(D14,Premissas!$A$40:$A$71,0))+INDEX(Premissas!$C$40:$C$71,MATCH(D14,Premissas!$A$40:$A$71,0))*Premissas!$B$30))) | H14: =IF(G14<Premissas!$B$36,MAX(Premissas!$B$33,G14*Premissas!$B$34),G14*Premissas!$B$35) | I14: =ROUND(G14+H14,2) | J14: =B14*Premissas!$B$8+Premissas!$B$9+Premissas!$B$10+Premissas!$B$11+Premissas!$B$12+ROUND(Premissas!$B$13*C14,2) | K14: =ROUNDUP((I14+J14-Premissas!$B$5*I14)/(1-Premissas!$B$6-Premissas!$B$7-Premissas!$B$5-Premissas!$B$14),2) | L14: =K14-F14 | M14: =L14/K14 | N14: =IF(K14>=F14,"Sim","NÃO") | O14: =(F14-I14-Premissas!$B$5*(F14-I14)-(Premissas!$B$6+Premissas!$B$7)*F14-J14)/F14 | P14: =F14*(1-Premissas!$B$6-Premissas!$B$7-Premissas!$B$5-Premissas!$B$14)-I14*(1-Premissas!$B$5)-(J14-Premissas!$B$12) | Q14: 21715.63 | R14: =K14-Q14
A15: Inversor | B15: 15 | C15: =B15*Premissas!$B$25 | D15: SOFAR 6KTLM-G3 | E15: 1 | F15: 21626.85 | G15: =(B15*Premissas!$B$24+(2*ROUNDUP(B15/2,0))*Premissas!$B$26+INT((2*ROUNDUP(B15/2,0))/4)*Premissas!$B$27+MOD((2*ROUNDUP(B15/2,0)),4)/2*Premissas!$B$28+2*IF(B15<=19,3*B15,IF(B15<=50,ROUNDUP(2.5*B15,0),2*B15))*Premissas!$B$29+IF(A15="Micro",E15*(Premissas!$B$31+Premissas!$B$32+4*Premissas!$B$30),E15*(INDEX(Premissas!$B$40:$B$71,MATCH(D15,Premissas!$A$40:$A$71,0))+INDEX(Premissas!$C$40:$C$71,MATCH(D15,Premissas!$A$40:$A$71,0))*Premissas!$B$30))) | H15: =IF(G15<Premissas!$B$36,MAX(Premissas!$B$33,G15*Premissas!$B$34),G15*Premissas!$B$35) | I15: =ROUND(G15+H15,2) | J15: =B15*Premissas!$B$8+Premissas!$B$9+Premissas!$B$10+Premissas!$B$11+Premissas!$B$12+ROUND(Premissas!$B$13*C15,2) | K15: =ROUNDUP((I15+J15-Premissas!$B$5*I15)/(1-Premissas!$B$6-Premissas!$B$7-Premissas!$B$5-Premissas!$B$14),2) | L15: =K15-F15 | M15: =L15/K15 | N15: =IF(K15>=F15,"Sim","NÃO") | O15: =(F15-I15-Premissas!$B$5*(F15-I15)-(Premissas!$B$6+Premissas!$B$7)*F15-J15)/F15 | P15: =F15*(1-Premissas!$B$6-Premissas!$B$7-Premissas!$B$5-Premissas!$B$14)-I15*(1-Premissas!$B$5)-(J15-Premissas!$B$12) | Q15: 23126.86 | R15: =K15-Q15
A16: Inversor | B16: 16 | C16: =B16*Premissas!$B$25 | D16: SOFAR 6KTLM-G3 | E16: 1 | F16: 22676.85 | G16: =(B16*Premissas!$B$24+(2*ROUNDUP(B16/2,0))*Premissas!$B$26+INT((2*ROUNDUP(B16/2,0))/4)*Premissas!$B$27+MOD((2*ROUNDUP(B16/2,0)),4)/2*Premissas!$B$28+2*IF(B16<=19,3*B16,IF(B16<=50,ROUNDUP(2.5*B16,0),2*B16))*Premissas!$B$29+IF(A16="Micro",E16*(Premissas!$B$31+Premissas!$B$32+4*Premissas!$B$30),E16*(INDEX(Premissas!$B$40:$B$71,MATCH(D16,Premissas!$A$40:$A$71,0))+INDEX(Premissas!$C$40:$C$71,MATCH(D16,Premissas!$A$40:$A$71,0))*Premissas!$B$30))) | H16: =IF(G16<Premissas!$B$36,MAX(Premissas!$B$33,G16*Premissas!$B$34),G16*Premissas!$B$35) | I16: =ROUND(G16+H16,2) | J16: =B16*Premissas!$B$8+Premissas!$B$9+Premissas!$B$10+Premissas!$B$11+Premissas!$B$12+ROUND(Premissas!$B$13*C16,2) | K16: =ROUNDUP((I16+J16-Premissas!$B$5*I16)/(1-Premissas!$B$6-Premissas!$B$7-Premissas!$B$5-Premissas!$B$14),2) | L16: =K16-F16 | M16: =L16/K16 | N16: =IF(K16>=F16,"Sim","NÃO") | O16: =(F16-I16-Premissas!$B$5*(F16-I16)-(Premissas!$B$6+Premissas!$B$7)*F16-J16)/F16 | P16: =F16*(1-Premissas!$B$6-Premissas!$B$7-Premissas!$B$5-Premissas!$B$14)-I16*(1-Premissas!$B$5)-(J16-Premissas!$B$12) | Q16: 24295.65 | R16: =K16-Q16
... A37: Micro | B37: 20 | C37: =B37*Premissas!$B$25 | D37: Microinversor HOYMILES 2,25kW | E37: 5 | F37: 32555.19 | G37: =(B37*Premissas!$B$24+(2*ROUNDUP(B37/2,0))*Premissas!$B$26+INT((2*ROUNDUP(B37/2,0))/4)*Premissas!$B$27+MOD((2*ROUNDUP(B37/2,0)),4)/2*Premissas!$B$28+2*IF(B37<=19,3*B37,IF(B37<=50,ROUNDUP(2.5*B37,0),2*B37))*Premissas!$B$29+IF(A37="Micro",E37*(Premissas!$B$31+Premissas!$B$32+4*Premissas!$B$30),E37*(INDEX(Premissas!$B$40:$B$71,MATCH(D37,Premissas!$A$40:$A$71,0))+INDEX(Premissas!$C$40:$C$71,MATCH(D37,Premissas!$A$40:$A$71,0))*Premissas!$B$30))) | H37: =IF(G37<Premissas!$B$36,MAX(Premissas!$B$33,G37*Premissas!$B$34),G37*Premissas!$B$35) | I37: =ROUND(G37+H37,2) | J37: =B37*Premissas!$B$8+Premissas!$B$9+Premissas!$B$10+Premissas!$B$11+Premissas!$B$12+ROUND(Premissas!$B$13*C37,2) | K37: =ROUNDUP((I37+J37-Premissas!$B$5*I37)/(1-Premissas!$B$6-Premissas!$B$7-Premissas!$B$5-Premissas!$B$14),2) | L37: =K37-F37 | M37: =L37/K37 | N37: =IF(K37>=F37,"Sim","NÃO") | O37: =(F37-I37-Premissas!$B$5*(F37-I37)-(Premissas!$B$6+Premissas!$B$7)*F37-J37)/F37 | P37: =F37*(1-Premissas!$B$6-Premissas!$B$7-Premissas!$B$5-Premissas!$B$14)-I37*(1-Premissas!$B$5)-(J37-Premissas!$B$12) | Q37: 34565.92 | R37: =K37-Q37
A39: Kits que cumprem a regra | F39: =COUNTIF(N5:N37,"Sim")&" de "&COUNT(B5:B37)
A40: Promocional mais barato, em média | F40: =AVERAGE(M5:M37)
A41: Menor folga (kit mais apertado) | F41: =MIN(L5:L37)
A42: Elétrica fixa mínima para os 33 cumprirem | F42: =ROUNDUP(MAX(P5:P37),0) | G42: com o R$/kWp das Premissas. Se a fixa nas Premissas ficar abaixo disso, algum kit quebra a regra.
A43: Diferença máxima Excel × plataforma | F43: =MAX(R5:R37)-MIN(R5:R37)

Sheet Catalogo
A1: Catálogo completo (Helte): preço de hoje (markup) × preço por custos
A2: É o que muda para o vendedor da Matriz quando ela escolher "Custos + margem alvo". Promocionais ficam fora.
A4: Kit | B4: Marca do inversor | C4: Tipo | D4: Módulos | E4: kWp | F4: Inversor | G4: Qtd inversores | H4: Ativo | I4: Preço hoje (markup, Matriz) | J4: Peças (R$) | K4: Frete (R$) | L4: Custo do kit c/ frete | M4: Custos fixos da obra | N4: Preço por custos | O4: "De" por custos | P4: Diferença (R$) | Q4: Diferença (%) | R4: Margem no preço de hoje | S4: Preço markup pela regra (custo atual)
A5: KIT 6 MOD. 620W + INV. CHINT 5KW | B5: CHINT | C5: Inversor | D5: 6 | E5: 3.72 | F5: CHINT CPS SCA5KTL-PSM1/EU | G5: 1 | H5: Sim | I5: 10706.85 | J5: =(D5*Premissas!$B$24+(2*ROUNDUP(D5/2,0))*Premissas!$B$26+INT((2*ROUNDUP(D5/2,0))/4)*Premissas!$B$27+MOD((2*ROUNDUP(D5/2,0)),4)/2*Premissas!$B$28+2*IF(D5<=19,3*D5,IF(D5<=50,ROUNDUP(2.5*D5,0),2*D5))*Premissas!$B$29+IF(C5="Micro",G5*(Premissas!$B$31+Premissas!$B$32+4*Premissas!$B$30),G5*(INDEX(Premissas!$B$40:$B$71,MATCH(F5,Premissas!$A$40:$A$71,0))+INDEX(Premissas!$C$40:$C$71,MATCH(F5,Premissas!$A$40:$A$71,0))*Premissas!$B$30))) | K5: =IF(J5<Premissas!$B$36,MAX(Premissas!$B$33,J5*Premissas!$B$34),J5*Premissas!$B$35) | L5: =ROUND(J5+K5,2) | M5: =D5*Premissas!$B$8+Premissas!$B$9+Premissas!$B$10+Premissas!$B$11+Premissas!$B$12+ROUND(Premissas!$B$13*E5,2) | N5: =ROUNDUP((L5+M5-Premissas!$B$5*L5)/(1-Premissas!$B$6-Premissas!$B$7-Premissas!$B$5-Premissas!$B$14),2) | O5: =ROUND(IF(N5<=30000,N5*(1+Premissas!$B$21),N5+Premissas!$B$21*30000*SQRT(N5/30000)),2) | P5: =N5-I5 | Q5: =P5/I5 | R5: =(I5-L5-Premissas!$B$5*(I5-L5)-(Premissas!$B$6+Premissas!$B$7)*I5-M5)/I5 | S5: =ROUND((CEILING((L5*Premissas!$B$17/Premissas!$B$18-97)/100,1)*100+97)*Premissas!$B$18,2)
A6: KIT 7 MOD. 620W + INV. CHINT 5KW | B6: CHINT | C6: Inversor | D6: 7 | E6: 4.34 | F6: CHINT CPS SCA5KTL-PSM1/EU | G6: 1 | H6: Sim | I6: 11966.85 | J6: =(D6*Premissas!$B$24+(2*ROUNDUP(D6/2,0))*Premissas!$B$26+INT((2*ROUNDUP(D6/2,0))/4)*Premissas!$B$27+MOD((2*ROUNDUP(D6/2,0)),4)/2*Premissas!$B$28+2*IF(D6<=19,3*D6,IF(D6<=50,ROUNDUP(2.5*D6,0),2*D6))*Premissas!$B$29+IF(C6="Micro",G6*(Premissas!$B$31+Premissas!$B$32+4*Premissas!$B$30),G6*(INDEX(Premissas!$B$40:$B$71,MATCH(F6,Premissas!$A$40:$A$71,0))+INDEX(Premissas!$C$40:$C$71,MATCH(F6,Premissas!$A$40:$A$71,0))*Premissas!$B$30))) | K6: =IF(J6<Premissas!$B$36,MAX(Premissas!$B$33,J6*Premissas!$B$34),J6*Premissas!$B$35) | L6: =ROUND(J6+K6,2) | M6: =D6*Premissas!$B$8+Premissas!$B$9+Premissas!$B$10+Premissas!$B$11+Premissas!$B$12+ROUND(Premissas!$B$13*E6,2) | N6: =ROUNDUP((L6+M6-Premissas!$B$5*L6)/(1-Premissas!$B$6-Premissas!$B$7-Premissas!$B$5-Premissas!$B$14),2) | O6: =ROUND(IF(N6<=30000,N6*(1+Premissas!$B$21),N6+Premissas!$B$21*30000*SQRT(N6/30000)),2) | P6: =N6-I6 | Q6: =P6/I6 | R6: =(I6-L6-Premissas!$B$5*(I6-L6)-(Premissas!$B$6+Premissas!$B$7)*I6-M6)/I6 | S6: =ROUND((CEILING((L6*Premissas!$B$17/Premissas!$B$18-97)/100,1)*100+97)*Premissas!$B$18,2)
A7: KIT 8 MOD. 620W + INV. CHINT 5KW | B7: CHINT | C7: Inversor | D7: 8 | E7: 4.96 | F7: CHINT CPS SCA5KTL-PSM1/EU | G7: 1 | H7: Sim | I7: 13016.85 | J7: =(D7*Premissas!$B$24+(2*ROUNDUP(D7/2,0))*Premissas!$B$26+INT((2*ROUNDUP(D7/2,0))/4)*Premissas!$B$27+MOD((2*ROUNDUP(D7/2,0)),4)/2*Premissas!$B$28+2*IF(D7<=19,3*D7,IF(D7<=50,ROUNDUP(2.5*D7,0),2*D7))*Premissas!$B$29+IF(C7="Micro",G7*(Premissas!$B$31+Premissas!$B$32+4*Premissas!$B$30),G7*(INDEX(Premissas!$B$40:$B$71,MATCH(F7,Premissas!$A$40:$A$71,0))+INDEX(Premissas!$C$40:$C$71,MATCH(F7,Premissas!$A$40:$A$71,0))*Premissas!$B$30))) | K7: =IF(J7<Premissas!$B$36,MAX(Premissas!$B$33,J7*Premissas!$B$34),J7*Premissas!$B$35) | L7: =ROUND(J7+K7,2) | M7: =D7*Premissas!$B$8+Premissas!$B$9+Premissas!$B$10+Premissas!$B$11+Premissas!$B$12+ROUND(Premissas!$B$13*E7,2) | N7: =ROUNDUP((L7+M7-Premissas!$B$5*L7)/(1-Premissas!$B$6-Premissas!$B$7-Premissas!$B$5-Premissas!$B$14),2) | O7: =ROUND(IF(N7<=30000,N7*(1+Premissas!$B$21),N7+Premissas!$B$21*30000*SQRT(N7/30000)),2) | P7: =N7-I7 | Q7: =P7/I7 | R7: =(I7-L7-Premissas!$B$5*(I7-L7)-(Premissas!$B$6+Premissas!$B$7)*I7-M7)/I7 | S7: =ROUND((CEILING((L7*Premissas!$B$17/Premissas!$B$18-97)/100,1)*100+97)*Premissas!$B$18,2)
A8: KIT 9 MOD. 620W + INV. CHINT 5KW | B8: CHINT | C8: Inversor | D8: 9 | E8: 5.58 | F8: CHINT CPS SCA5KTL-PSM1/EU | G8: 1 | H8: Sim | I8: 14276.85 | J8: =(D8*Premissas!$B$24+(2*ROUNDUP(D8/2,0))*Premissas!$B$26+INT((2*ROUNDUP(D8/2,0))/4)*Premissas!$B$27+MOD((2*ROUNDUP(D8/2,0)),4)/2*Premissas!$B$28+2*IF(D8<=19,3*D8,IF(D8<=50,ROUNDUP(2.5*D8,0),2*D8))*Premissas!$B$29+IF(C8="Micro",G8*(Premissas!$B$31+Premissas!$B$32+4*Premissas!$B$30),G8*(INDEX(Premissas!$B$40:$B$71,MATCH(F8,Premissas!$A$40:$A$71,0))+INDEX(Premissas!$C$40:$C$71,MATCH(F8,Premissas!$A$40:$A$71,0))*Premissas!$B$30))) | K8: =IF(J8<Premissas!$B$36,MAX(Premissas!$B$33,J8*Premissas!$B$34),J8*Premissas!$B$35) | L8: =ROUND(J8+K8,2) | M8: =D8*Premissas!$B$8+Premissas!$B$9+Premissas!$B$10+Premissas!$B$11+Premissas!$B$12+ROUND(Premissas!$B$13*E8,2) | N8: =ROUNDUP((L8+M8-Premissas!$B$5*L8)/(1-Premissas!$B$6-Premissas!$B$7-Premissas!$B$5-Premissas!$B$14),2) | O8: =ROUND(IF(N8<=30000,N8*(1+Premissas!$B$21),N8+Premissas!$B$21*30000*SQRT(N8/30000)),2) | P8: =N8-I8 | Q8: =P8/I8 | R8: =(I8-L8-Premissas!$B$5*(I8-L8)-(Premissas!$B$6+Premissas!$B$7)*I8-M8)/I8 | S8: =ROUND((CEILING((L8*Premissas!$B$17/Premissas!$B$18-97)/100,1)*100+97)*Premissas!$B$18,2)
A9: KIT 10 MOD. 620W + INV. CHINT 5KW | B9: CHINT | C9: Inversor | D9: 10 | E9: 6.2 | F9: CHINT CPS SCA5KTL-PSM1/EU | G9: 1 | H9: Sim | I9: 15326.85 | J9: =(D9*Premissas!$B$24+(2*ROUNDUP(D9/2,0))*Premissas!$B$26+INT((2*ROUNDUP(D9/2,0))/4)*Premissas!$B$27+MOD((2*ROUNDUP(D9/2,0)),4)/2*Premissas!$B$28+2*IF(D9<=19,3*D9,IF(D9<=50,ROUNDUP(2.5*D9,0),2*D9))*Premissas!$B$29+IF(C9="Micro",G9*(Premissas!$B$31+Premissas!$B$32+4*Premissas!$B$30),G9*(INDEX(Premissas!$B$40:$B$71,MATCH(F9,Premissas!$A$40:$A$71,0))+INDEX(Premissas!$C$40:$C$71,MATCH(F9,Premissas!$A$40:$A$71,0))*Premissas!$B$30))) | K9: =IF(J9<Premissas!$B$36,MAX(Premissas!$B$33,J9*Premissas!$B$34),J9*Premissas!$B$35) | L9: =ROUND(J9+K9,2) | M9: =D9*Premissas!$B$8+Premissas!$B$9+Premissas!$B$10+Premissas!$B$11+Premissas!$B$12+ROUND(Premissas!$B$13*E9,2) | N9: =ROUNDUP((L9+M9-Premissas!$B$5*L9)/(1-Premissas!$B$6-Premissas!$B$7-Premissas!$B$5-Premissas!$B$14),2) | O9: =ROUND(IF(N9<=30000,N9*(1+Premissas!$B$21),N9+Premissas!$B$21*30000*SQRT(N9/30000)),2) | P9: =N9-I9 | Q9: =P9/I9 | R9: =(I9-L9-Premissas!$B$5*(I9-L9)-(Premissas!$B$6+Premissas!$B$7)*I9-M9)/I9 | S9: =ROUND((CEILING((L9*Premissas!$B$17/Premissas!$B$18-97)/100,1)*100+97)*Premissas!$B$18,2)
A10: KIT 11 MOD. 620W + INV. CHINT 5KW | B10: CHINT | C10: Inversor | D10: 11 | E10: 6.82 | F10: CHINT CPS SCA5KTL-PSM1/EU | G10: 1 | H10: Sim | I10: 16586.85 | J10: =(D10*Premissas!$B$24+(2*ROUNDUP(D10/2,0))*Premissas!$B$26+INT((2*ROUNDUP(D10/2,0))/4)*Premissas!$B$27+MOD((2*ROUNDUP(D10/2,0)),4)/2*Premissas!$B$28+2*IF(D10<=19,3*D10,IF(D10<=50,ROUNDUP(2.5*D10,0),2*D10))*Premissas!$B$29+IF(C10="Micro",G10*(Premissas!$B$31+Premissas!$B$32+4*Premissas!$B$30),G10*(INDEX(Premissas!$B$40:$B$71,MATCH(F10,Premissas!$A$40:$A$71,0))+INDEX(Premissas!$C$40:$C$71,MATCH(F10,Premissas!$A$40:$A$71,0))*Premissas!$B$30))) | K10: =IF(J10<Premissas!$B$36,MAX(Premissas!$B$33,J10*Premissas!$B$34),J10*Premissas!$B$35) | L10: =ROUND(J10+K10,2) | M10: =D10*Premissas!$B$8+Premissas!$B$9+Premissas!$B$10+Premissas!$B$11+Premissas!$B$12+ROUND(Premissas!$B$13*E10,2) | N10: =ROUNDUP((L10+M10-Premissas!$B$5*L10)/(1-Premissas!$B$6-Premissas!$B$7-Premissas!$B$5-Premissas!$B$14),2) | O10: =ROUND(IF(N10<=30000,N10*(1+Premissas!$B$21),N10+Premissas!$B$21*30000*SQRT(N10/30000)),2) | P10: =N10-I10 | Q10: =P10/I10 | R10: =(I10-L10-Premissas!$B$5*(I10-L10)-(Premissas!$B$6+Premissas!$B$7)*I10-M10)/I10 | S10: =ROUND((CEILING((L10*Premissas!$B$17/Premissas!$B$18-97)/100,1)*100+97)*Premissas!$B$18,2)
A11: KIT 12 MOD. 620W + INV. CHINT 5KW | B11: CHINT | C11: Inversor | D11: 12 | E11: 7.44 | F11: CHINT CPS SCA5KTL-PSM1/EU | G11: 1 | H11: Sim | I11: 17636.85 | J11: =(D11*Premissas!$B$24+(2*ROUNDUP(D11/2,0))*Premissas!$B$26+INT((2*ROUNDUP(D11/2,0))/4)*Premissas!$B$27+MOD((2*ROUNDUP(D11/2,0)),4)/2*Premissas!$B$28+2*IF(D11<=19,3*D11,IF(D11<=50,ROUNDUP(2.5*D11,0),2*D11))*Premissas!$B$29+IF(C11="Micro",G11*(Premissas!$B$31+Premissas!$B$32+4*Premissas!$B$30),G11*(INDEX(Premissas!$B$40:$B$71,MATCH(F11,Premissas!$A$40:$A$71,0))+INDEX(Premissas!$C$40:$C$71,MATCH(F11,Premissas!$A$40:$A$71,0))*Premissas!$B$30))) | K11: =IF(J11<Premissas!$B$36,MAX(Premissas!$B$33,J11*Premissas!$B$34),J11*Premissas!$B$35) | L11: =ROUND(J11+K11,2) | M11: =D11*Premissas!$B$8+Premissas!$B$9+Premissas!$B$10+Premissas!$B$11+Premissas!$B$12+ROUND(Premissas!$B$13*E11,2) | N11: =ROUNDUP((L11+M11-Premissas!$B$5*L11)/(1-Premissas!$B$6-Premissas!$B$7-Premissas!$B$5-Premissas!$B$14),2) | O11: =ROUND(IF(N11<=30000,N11*(1+Premissas!$B$21),N11+Premissas!$B$21*30000*SQRT(N11/30000)),2) | P11: =N11-I11 | Q11: =P11/I11 | R11: =(I11-L11-Premissas!$B$5*(I11-L11)-(Premissas!$B$6+Premissas!$B$7)*I11-M11)/I11 | S11: =ROUND((CEILING((L11*Premissas!$B$17/Premissas!$B$18-97)/100,1)*100+97)*Premissas!$B$18,2)
A12: KIT 13 MOD. 620W + INV. CHINT 5KW | B12: CHINT | C12: Inversor | D12: 13 | E12: 8.06 | F12: CHINT CPS SCA5KTL-PSM1/EU | G12: 1 | H12: Sim | I12: 18896.85 | J12: =(D12*Premissas!$B$24+(2*ROUNDUP(D12/2,0))*Premissas!$B$26+INT((2*ROUNDUP(D12/2,0))/4)*Premissas!$B$27+MOD((2*ROUNDUP(D12/2,0)),4)/2*Premissas!$B$28+2*IF(D12<=19,3*D12,IF(D12<=50,ROUNDUP(2.5*D12,0),2*D12))*Premissas!$B$29+IF(C12="Micro",G12*(Premissas!$B$31+Premissas!$B$32+4*Premissas!$B$30),G12*(INDEX(Premissas!$B$40:$B$71,MATCH(F12,Premissas!$A$40:$A$71,0))+INDEX(Premissas!$C$40:$C$71,MATCH(F12,Premissas!$A$40:$A$71,0))*Premissas!$B$30))) | K12: =IF(J12<Premissas!$B$36,MAX(Premissas!$B$33,J12*Premissas!$B$34),J12*Premissas!$B$35) | L12: =ROUND(J12+K12,2) | M12: =D12*Premissas!$B$8+Premissas!$B$9+Premissas!$B$10+Premissas!$B$11+Premissas!$B$12+ROUND(Premissas!$B$13*E12,2) | N12: =ROUNDUP((L12+M12-Premissas!$B$5*L12)/(1-Premissas!$B$6-Premissas!$B$7-Premissas!$B$5-Premissas!$B$14),2) | O12: =ROUND(IF(N12<=30000,N12*(1+Premissas!$B$21),N12+Premissas!$B$21*30000*SQRT(N12/30000)),2) | P12: =N12-I12 | Q12: =P12/I12 | R12: =(I12-L12-Premissas!$B$5*(I12-L12)-(Premissas!$B$6+Premissas!$B$7)*I12-M12)/I12 | S12: =ROUND((CEILING((L12*Premissas!$B$17/Premissas!$B$18-97)/100,1)*100+97)*Premissas!$B$18,2)
A13: KIT 14 MOD. 620W + INV. CHINT 6KW | B13: CHINT | C13: Inversor | D13: 14 | E13: 8.68 | F13: CHINT CPS SCA6KTL-PSM3/EU | G13: 1 | H13: Sim | I13: 20156.85 | J13: =(D13*Premissas!$B$24+(2*ROUNDUP(D13/2,0))*Premissas!$B$26+INT((2*ROUNDUP(D13/2,0))/4)*Premissas!$B$27+MOD((2*ROUNDUP(D13/2,0)),4)/2*Premissas!$B$28+2*IF(D13<=19,3*D13,IF(D13<=50,ROUNDUP(2.5*D13,0),2*D13))*Premissas!$B$29+IF(C13="Micro",G13*(Premissas!$B$31+Premissas!$B$32+4*Premissas!$B$30),G13*(INDEX(Premissas!$B$40:$B$71,MATCH(F13,Premissas!$A$40:$A$71,0))+INDEX(Premissas!$C$40:$C$71,MATCH(F13,Premissas!$A$40:$A$71,0))*Premissas!$B$30))) | K13: =IF(J13<Premissas!$B$36,MAX(Premissas!$B$33,J13*Premissas!$B$34),J13*Premissas!$B$35) | L13: =ROUND(J13+K13,2) | M13: =D13*Premissas!$B$8+Premissas!$B$9+Premissas!$B$10+Premissas!$B$11+Premissas!$B$12+ROUND(Premissas!$B$13*E13,2) | N13: =ROUNDUP((L13+M13-Premissas!$B$5*L13)/(1-Premissas!$B$6-Premissas!$B$7-Premissas!$B$5-Premissas!$B$14),2) | O13: =ROUND(IF(N13<=30000,N13*(1+Premissas!$B$21),N13+Premissas!$B$21*30000*SQRT(N13/30000)),2) | P13: =N13-I13 | Q13: =P13/I13 | R13: =(I13-L13-Premissas!$B$5*(I13-L13)-(Premissas!$B$6+Premissas!$B$7)*I13-M13)/I13 | S13: =ROUND((CEILING((L13*Premissas!$B$17/Premissas!$B$18-97)/100,1)*100+97)*Premissas!$B$18,2)
A14: KIT 15 MOD. 620W + INV. CHINT 6KW | B14: CHINT | C14: Inversor | D14: 15 | E14: 9.3 | F14: CHINT CPS SCA6KTL-PSM3/EU | G14: 1 | H14: Sim | I14: 21521.85 | J14: =(D14*Premissas!$B$24+(2*ROUNDUP(D14/2,0))*Premissas!$B$26+INT((2*ROUNDUP(D14/2,0))/4)*Premissas!$B$27+MOD((2*ROUNDUP(D14/2,0)),4)/2*Premissas!$B$28+2*IF(D14<=19,3*D14,IF(D14<=50,ROUNDUP(2.5*D14,0),2*D14))*Premissas!$B$29+IF(C14="Micro",G14*(Premissas!$B$31+Premissas!$B$32+4*Premissas!$B$30),G14*(INDEX(Premissas!$B$40:$B$71,MATCH(F14,Premissas!$A$40:$A$71,0))+INDEX(Premissas!$C$40:$C$71,MATCH(F14,Premissas!$A$40:$A$71,0))*Premissas!$B$30))) | K14: =IF(J14<Premissas!$B$36,MAX(Premissas!$B$33,J14*Premissas!$B$34),J14*Premissas!$B$35) | L14: =ROUND(J14+K14,2) | M14: =D14*Premissas!$B$8+Premissas!$B$9+Premissas!$B$10+Premissas!$B$11+Premissas!$B$12+ROUND(Premissas!$B$13*E14,2) | N14: =ROUNDUP((L14+M14-Premissas!$B$5*L14)/(1-Premissas!$B$6-Premissas!$B$7-Premissas!$B$5-Premissas!$B$14),2) | O14: =ROUND(IF(N14<=30000,N14*(1+Premissas!$B$21),N14+Premissas!$B$21*30000*SQRT(N14/30000)),2) | P14: =N14-I14 | Q14: =P14/I14 | R14: =(I14-L14-Premissas!$B$5*(I14-L14)-(Premissas!$B$6+Premissas!$B$7)*I14-M14)/I14 | S14: =ROUND((CEILING((L14*Premissas!$B$17/Premissas!$B$18-97)/100,1)*100+97)*Premissas!$B$18,2)
A15: KIT 16 MOD. 620W + INV. CHINT 6KW | B15: CHINT | C15: Inversor | D15: 16 | E15: 9.92 | F15: CHINT CPS SCA6KTL-PSM3/EU | G15: 1 | H15: Sim | I15: 22571.85 | J15: =(D15*Premissas!$B$24+(2*ROUNDUP(D15/2,0))*Premissas!$B$26+INT((2*ROUNDUP(D15/2,0))/4)*Premissas!$B$27+MOD((2*ROUNDUP(D15/2,0)),4)/2*Premissas!$B$28+2*IF(D15<=19,3*D15,IF(D15<=50,ROUNDUP(2.5*D15,0),2*D15))*Premissas!$B$29+IF(C15="Micro",G15*(Premissas!$B$31+Premissas!$B$32+4*Premissas!$B$30),G15*(INDEX(Premissas!$B$40:$B$71,MATCH(F15,Premissas!$A$40:$A$71,0))+INDEX(Premissas!$C$40:$C$71,MATCH(F15,Premissas!$A$40:$A$71,0))*Premissas!$B$30))) | K15: =IF(J15<Premissas!$B$36,MAX(Premissas!$B$33,J15*Premissas!$B$34),J15*Premissas!$B$35) | L15: =ROUND(J15+K15,2) | M15: =D15*Premissas!$B$8+Premissas!$B$9+Premissas!$B$10+Premissas!$B$11+Premissas!$B$12+ROUND(Premissas!$B$13*E15,2) | N15: =ROUNDUP((L15+M15-Premissas!$B$5*L15)/(1-Premissas!$B$6-Premissas!$B$7-Premissas!$B$5-Premissas!$B$14),2) | O15: =ROUND(IF(N15<=30000,N15*(1+Premissas!$B$21),N15+Premissas!$B$21*30000*SQRT(N15/30000)),2) | P15: =N15-I15 | Q15: =P15/I15 | R15: =(I15-L15-Premissas!$B$5*(I15-L15)-(Premissas!$B$6+Premissas!$B$7)*I15-M15)/I15 | S15: =ROUND((CEILING((L15*Premissas!$B$17/Premissas!$B$18-97)/100,1)*100+97)*Premissas!$B$18,2)
A16: KIT 17 MOD. 620W + INV. CHINT 7,5KW | B16: CHINT | C16: Inversor | D16: 17 | E16: 10.54 | F16: CHINT 7,5K | G16: 1 | H16: Sim | I16: 25091.85 | J16: =(D16*Premissas!$B$24+(2*ROUNDUP(D16/2,0))*Premissas!$B$26+INT((2*ROUNDUP(D16/2,0))/4)*Premissas!$B$27+MOD((2*ROUNDUP(D16/2,0)),4)/2*Premissas!$B$28+2*IF(D16<=19,3*D16,IF(D16<=50,ROUNDUP(2.5*D16,0),2*D16))*Premissas!$B$29+IF(C16="Micro",G16*(Premissas!$B$31+Premissas!$B$32+4*Premissas!$B$30),G16*(INDEX(Premissas!$B$40:$B$71,MATCH(F16,Premissas!$A$40:$A$71,0))+INDEX(Premissas!$C$40:$C$71,MATCH(F16,Premissas!$A$40:$A$71,0))*Premissas!$B$30))) | K16: =IF(J16<Premissas!$B$36,MAX(Premissas!$B$33,J16*Premissas!$B$34),J16*Premissas!$B$35) | L16: =ROUND(J16+K16,2) | M16: =D16*Premissas!$B$8+Premissas!$B$9+Premissas!$B$10+Premissas!$B$11+Premissas!$B$12+ROUND(Premissas!$B$13*E16,2) | N16: =ROUNDUP((L16+M16-Premissas!$B$5*L16)/(1-Premissas!$B$6-Premissas!$B$7-Premissas!$B$5-Premissas!$B$14),2) | O16: =ROUND(IF(N16<=30000,N16*(1+Premissas!$B$21),N16+Premissas!$B$21*30000*SQRT(N16/30000)),2) | P16: =N16-I16 | Q16: =P16/I16 | R16: =(I16-L16-Premissas!$B$5*(I16-L16)-(Premissas!$B$6+Premissas!$B$7)*I16-M16)/I16 | S16: =ROUND((CEILING((L16*Premissas!$B$17/Premissas!$B$18-97)/100,1)*100+97)*Premissas!$B$18,2)
... A444: KIT 150 MOD. 620W + INV. SOLIS 75KW | B444: SOLIS | C444: Inversor | D444: 150 | E444: 93 | F444: SOLIS S6-GC-75K-LV TRI 220V | G444: 1 | H444: Sim | I444: 214196.85 | J444: =(D444*Premissas!$B$24+(2*ROUNDUP(D444/2,0))*Premissas!$B$26+INT((2*ROUNDUP(D444/2,0))/4)*Premissas!$B$27+MOD((2*ROUNDUP(D444/2,0)),4)/2*Premissas!$B$28+2*IF(D444<=19,3*D444,IF(D444<=50,ROUNDUP(2.5*D444,0),2*D444))*Premissas!$B$29+IF(C444="Micro",G444*(Premissas!$B$31+Premissas!$B$32+4*Premissas!$B$30),G444*(INDEX(Premissas!$B$40:$B$71,MATCH(F444,Premissas!$A$40:$A$71,0))+INDEX(Premissas!$C$40:$C$71,MATCH(F444,Premissas!$A$40:$A$71,0))*Premissas!$B$30))) | K444: =IF(J444<Premissas!$B$36,MAX(Premissas!$B$33,J444*Premissas!$B$34),J444*Premissas!$B$35) | L444: =ROUND(J444+K444,2) | M444: =D444*Premissas!$B$8+Premissas!$B$9+Premissas!$B$10+Premissas!$B$11+Premissas!$B$12+ROUND(Premissas!$B$13*E444,2) | N444: =ROUNDUP((L444+M444-Premissas!$B$5*L444)/(1-Premissas!$B$6-Premissas!$B$7-Premissas!$B$5-Premissas!$B$14),2) | O444: =ROUND(IF(N444<=30000,N444*(1+Premissas!$B$21),N444+Premissas!$B$21*30000*SQRT(N444/30000)),2) | P444: =N444-I444 | Q444: =P444/I444 | R444: =(I444-L444-Premissas!$B$5*(I444-L444)-(Premissas!$B$6+Premissas!$B$7)*I444-M444)/I444 | S444: =ROUND((CEILING((L444*Premissas!$B$17/Premissas!$B$18-97)/100,1)*100+97)*Premissas!$B$18,2)
A445: KIT 4 MOD. 620W + MICROINVERSOR HOYMILES 2,25KW | B445: HOYMILES | C445: Micro | D445: 4 | E445: 2.48 | F445: Microinversor HOYMILES 2,25kW | G445: 1 | H445: Sim | I445: 8029.29 | J445: =(D445*Premissas!$B$24+(2*ROUNDUP(D445/2,0))*Premissas!$B$26+INT((2*ROUNDUP(D445/2,0))/4)*Premissas!$B$27+MOD((2*ROUNDUP(D445/2,0)),4)/2*Premissas!$B$28+2*IF(D445<=19,3*D445,IF(D445<=50,ROUNDUP(2.5*D445,0),2*D445))*Premissas!$B$29+IF(C445="Micro",G445*(Premissas!$B$31+Premissas!$B$32+4*Premissas!$B$30),G445*(INDEX(Premissas!$B$40:$B$71,MATCH(F445,Premissas!$A$40:$A$71,0))+INDEX(Premissas!$C$40:$C$71,MATCH(F445,Premissas!$A$40:$A$71,0))*Premissas!$B$30))) | K445: =IF(J445<Premissas!$B$36,MAX(Premissas!$B$33,J445*Premissas!$B$34),J445*Premissas!$B$35) | L445: =ROUND(J445+K445,2) | M445: =D445*Premissas!$B$8+Premissas!$B$9+Premissas!$B$10+Premissas!$B$11+Premissas!$B$12+ROUND(Premissas!$B$13*E445,2) | N445: =ROUNDUP((L445+M445-Premissas!$B$5*L445)/(1-Premissas!$B$6-Premissas!$B$7-Premissas!$B$5-Premissas!$B$14),2) | O445: =ROUND(IF(N445<=30000,N445*(1+Premissas!$B$21),N445+Premissas!$B$21*30000*SQRT(N445/30000)),2) | P445: =N445-I445 | Q445: =P445/I445 | R445: =(I445-L445-Premissas!$B$5*(I445-L445)-(Premissas!$B$6+Premissas!$B$7)*I445-M445)/I445 | S445: =ROUND((CEILING((L445*Premissas!$B$19/Premissas!$B$20-97)/100,1)*100+97)*Premissas!$B$20,2)
A446: KIT 5 MOD. 620W + MICROINVERSOR HOYMILES 2,25KW | B446: HOYMILES | C446: Micro | D446: 5 | E446: 3.1 | F446: Microinversor HOYMILES 2,25kW | G446: 2 | H446: Sim | I446: 10171.29 | J446: =(D446*Premissas!$B$24+(2*ROUNDUP(D446/2,0))*Premissas!$B$26+INT((2*ROUNDUP(D446/2,0))/4)*Premissas!$B$27+MOD((2*ROUNDUP(D446/2,0)),4)/2*Premissas!$B$28+2*IF(D446<=19,3*D446,IF(D446<=50,ROUNDUP(2.5*D446,0),2*D446))*Premissas!$B$29+IF(C446="Micro",G446*(Premissas!$B$31+Premissas!$B$32+4*Premissas!$B$30),G446*(INDEX(Premissas!$B$40:$B$71,MATCH(F446,Premissas!$A$40:$A$71,0))+INDEX(Premissas!$C$40:$C$71,MATCH(F446,Premissas!$A$40:$A$71,0))*Premissas!$B$30))) | K446: =IF(J446<Premissas!$B$36,MAX(Premissas!$B$33,J446*Premissas!$B$34),J446*Premissas!$B$35) | L446: =ROUND(J446+K446,2) | M446: =D446*Premissas!$B$8+Premissas!$B$9+Premissas!$B$10+Premissas!$B$11+Premissas!$B$12+ROUND(Premissas!$B$13*E446,2) | N446: =ROUNDUP((L446+M446-Premissas!$B$5*L446)/(1-Premissas!$B$6-Premissas!$B$7-Premissas!$B$5-Premissas!$B$14),2) | O446: =ROUND(IF(N446<=30000,N446*(1+Premissas!$B$21),N446+Premissas!$B$21*30000*SQRT(N446/30000)),2) | P446: =N446-I446 | Q446: =P446/I446 | R446: =(I446-L446-Premissas!$B$5*(I446-L446)-(Premissas!$B$6+Premissas!$B$7)*I446-M446)/I446 | S446: =ROUND((CEILING((L446*Premissas!$B$19/Premissas!$B$20-97)/100,1)*100+97)*Premissas!$B$20,2)
A447: KIT 6 MOD. 620W + MICROINVERSOR HOYMILES 2,25KW | B447: HOYMILES | C447: Micro | D447: 6 | E447: 3.72 | F447: Microinversor HOYMILES 2,25kW | G447: 2 | H447: Sim | I447: 11135.19 | J447: =(D447*Premissas!$B$24+(2*ROUNDUP(D447/2,0))*Premissas!$B$26+INT((2*ROUNDUP(D447/2,0))/4)*Premissas!$B$27+MOD((2*ROUNDUP(D447/2,0)),4)/2*Premissas!$B$28+2*IF(D447<=19,3*D447,IF(D447<=50,ROUNDUP(2.5*D447,0),2*D447))*Premissas!$B$29+IF(C447="Micro",G447*(Premissas!$B$31+Premissas!$B$32+4*Premissas!$B$30),G447*(INDEX(Premissas!$B$40:$B$71,MATCH(F447,Premissas!$A$40:$A$71,0))+INDEX(Premissas!$C$40:$C$71,MATCH(F447,Premissas!$A$40:$A$71,0))*Premissas!$B$30))) | K447: =IF(J447<Premissas!$B$36,MAX(Premissas!$B$33,J447*Premissas!$B$34),J447*Premissas!$B$35) | L447: =ROUND(J447+K447,2) | M447: =D447*Premissas!$B$8+Premissas!$B$9+Premissas!$B$10+Premissas!$B$11+Premissas!$B$12+ROUND(Premissas!$B$13*E447,2) | N447: =ROUNDUP((L447+M447-Premissas!$B$5*L447)/(1-Premissas!$B$6-Premissas!$B$7-Premissas!$B$5-Premissas!$B$14),2) | O447: =ROUND(IF(N447<=30000,N447*(1+Premissas!$B$21),N447+Premissas!$B$21*30000*SQRT(N447/30000)),2) | P447: =N447-I447 | Q447: =P447/I447 | R447: =(I447-L447-Premissas!$B$5*(I447-L447)-(Premissas!$B$6+Premissas!$B$7)*I447-M447)/I447 | S447: =ROUND((CEILING((L447*Premissas!$B$19/Premissas!$B$20-97)/100,1)*100+97)*Premissas!$B$20,2)
A448: KIT 7 MOD. 620W + MICROINVERSOR HOYMILES 2,25KW | B448: HOYMILES | C448: Micro | D448: 7 | E448: 4.34 | F448: Microinversor HOYMILES 2,25kW | G448: 2 | H448: Sim | I448: 12420.39 | J448: =(D448*Premissas!$B$24+(2*ROUNDUP(D448/2,0))*Premissas!$B$26+INT((2*ROUNDUP(D448/2,0))/4)*Premissas!$B$27+MOD((2*ROUNDUP(D448/2,0)),4)/2*Premissas!$B$28+2*IF(D448<=19,3*D448,IF(D448<=50,ROUNDUP(2.5*D448,0),2*D448))*Premissas!$B$29+IF(C448="Micro",G448*(Premissas!$B$31+Premissas!$B$32+4*Premissas!$B$30),G448*(INDEX(Premissas!$B$40:$B$71,MATCH(F448,Premissas!$A$40:$A$71,0))+INDEX(Premissas!$C$40:$C$71,MATCH(F448,Premissas!$A$40:$A$71,0))*Premissas!$B$30))) | K448: =IF(J448<Premissas!$B$36,MAX(Premissas!$B$33,J448*Premissas!$B$34),J448*Premissas!$B$35) | L448: =ROUND(J448+K448,2) | M448: =D448*Premissas!$B$8+Premissas!$B$9+Premissas!$B$10+Premissas!$B$11+Premissas!$B$12+ROUND(Premissas!$B$13*E448,2) | N448: =ROUNDUP((L448+M448-Premissas!$B$5*L448)/(1-Premissas!$B$6-Premissas!$B$7-Premissas!$B$5-Premissas!$B$14),2) | O448: =ROUND(IF(N448<=30000,N448*(1+Premissas!$B$21),N448+Premissas!$B$21*30000*SQRT(N448/30000)),2) | P448: =N448-I448 | Q448: =P448/I448 | R448: =(I448-L448-Premissas!$B$5*(I448-L448)-(Premissas!$B$6+Premissas!$B$7)*I448-M448)/I448 | S448: =ROUND((CEILING((L448*Premissas!$B$19/Premissas!$B$20-97)/100,1)*100+97)*Premissas!$B$20,2)
A449: KIT 8 MOD. 620W + MICROINVERSOR HOYMILES 2,25KW | B449: HOYMILES | C449: Micro | D449: 8 | E449: 4.96 | F449: Microinversor HOYMILES 2,25kW | G449: 2 | H449: Sim | I449: 13598.49 | J449: =(D449*Premissas!$B$24+(2*ROUNDUP(D449/2,0))*Premissas!$B$26+INT((2*ROUNDUP(D449/2,0))/4)*Premissas!$B$27+MOD((2*ROUNDUP(D449/2,0)),4)/2*Premissas!$B$28+2*IF(D449<=19,3*D449,IF(D449<=50,ROUNDUP(2.5*D449,0),2*D449))*Premissas!$B$29+IF(C449="Micro",G449*(Premissas!$B$31+Premissas!$B$32+4*Premissas!$B$30),G449*(INDEX(Premissas!$B$40:$B$71,MATCH(F449,Premissas!$A$40:$A$71,0))+INDEX(Premissas!$C$40:$C$71,MATCH(F449,Premissas!$A$40:$A$71,0))*Premissas!$B$30))) | K449: =IF(J449<Premissas!$B$36,MAX(Premissas!$B$33,J449*Premissas!$B$34),J449*Premissas!$B$35) | L449: =ROUND(J449+K449,2) | M449: =D449*Premissas!$B$8+Premissas!$B$9+Premissas!$B$10+Premissas!$B$11+Premissas!$B$12+ROUND(Premissas!$B$13*E449,2) | N449: =ROUNDUP((L449+M449-Premissas!$B$5*L449)/(1-Premissas!$B$6-Premissas!$B$7-Premissas!$B$5-Premissas!$B$14),2) | O449: =ROUND(IF(N449<=30000,N449*(1+Premissas!$B$21),N449+Premissas!$B$21*30000*SQRT(N449/30000)),2) | P449: =N449-I449 | Q449: =P449/I449 | R449: =(I449-L449-Premissas!$B$5*(I449-L449)-(Premissas!$B$6+Premissas!$B$7)*I449-M449)/I449 | S449: =ROUND((CEILING((L449*Premissas!$B$19/Premissas!$B$20-97)/100,1)*100+97)*Premissas!$B$20,2)
A450: KIT 9 MOD. 620W + MICROINVERSOR HOYMILES 2,25KW | B450: HOYMILES | C450: Micro | D450: 9 | E450: 5.58 | F450: Microinversor HOYMILES 2,25kW | G450: 3 | H450: Sim | I450: 16383.09 | J450: =(D450*Premissas!$B$24+(2*ROUNDUP(D450/2,0))*Premissas!$B$26+INT((2*ROUNDUP(D450/2,0))/4)*Premissas!$B$27+MOD((2*ROUNDUP(D450/2,0)),4)/2*Premissas!$B$28+2*IF(D450<=19,3*D450,IF(D450<=50,ROUNDUP(2.5*D450,0),2*D450))*Premissas!$B$29+IF(C450="Micro",G450*(Premissas!$B$31+Premissas!$B$32+4*Premissas!$B$30),G450*(INDEX(Premissas!$B$40:$B$71,MATCH(F450,Premissas!$A$40:$A$71,0))+INDEX(Premissas!$C$40:$C$71,MATCH(F450,Premissas!$A$40:$A$71,0))*Premissas!$B$30))) | K450: =IF(J450<Premissas!$B$36,MAX(Premissas!$B$33,J450*Premissas!$B$34),J450*Premissas!$B$35) | L450: =ROUND(J450+K450,2) | M450: =D450*Premissas!$B$8+Premissas!$B$9+Premissas!$B$10+Premissas!$B$11+Premissas!$B$12+ROUND(Premissas!$B$13*E450,2) | N450: =ROUNDUP((L450+M450-Premissas!$B$5*L450)/(1-Premissas!$B$6-Premissas!$B$7-Premissas!$B$5-Premissas!$B$14),2) | O450: =ROUND(IF(N450<=30000,N450*(1+Premissas!$B$21),N450+Premissas!$B$21*30000*SQRT(N450/30000)),2) | P450: =N450-I450 | Q450: =P450/I450 | R450: =(I450-L450-Premissas!$B$5*(I450-L450)-(Premissas!$B$6+Premissas!$B$7)*I450-M450)/I450 | S450: =ROUND((CEILING((L450*Premissas!$B$19/Premissas!$B$20-97)/100,1)*100+97)*Premissas!$B$20,2)
A451: KIT 10 MOD. 620W + MICROINVERSOR HOYMILES 2,25KW | B451: HOYMILES | C451: Micro | D451: 10 | E451: 6.2 | F451: Microinversor HOYMILES 2,25kW | G451: 3 | H451: Sim | I451: 17454.09 | J451: =(D451*Premissas!$B$24+(2*ROUNDUP(D451/2,0))*Premissas!$B$26+INT((2*ROUNDUP(D451/2,0))/4)*Premissas!$B$27+MOD((2*ROUNDUP(D451/2,0)),4)/2*Premissas!$B$28+2*IF(D451<=19,3*D451,IF(D451<=50,ROUNDUP(2.5*D451,0),2*D451))*Premissas!$B$29+IF(C451="Micro",G451*(Premissas!$B$31+Premissas!$B$32+4*Premissas!$B$30),G451*(INDEX(Premissas!$B$40:$B$71,MATCH(F451,Premissas!$A$40:$A$71,0))+INDEX(Premissas!$C$40:$C$71,MATCH(F451,Premissas!$A$40:$A$71,0))*Premissas!$B$30))) | K451: =IF(J451<Premissas!$B$36,MAX(Premissas!$B$33,J451*Premissas!$B$34),J451*Premissas!$B$35) | L451: =ROUND(J451+K451,2) | M451: =D451*Premissas!$B$8+Premissas!$B$9+Premissas!$B$10+Premissas!$B$11+Premissas!$B$12+ROUND(Premissas!$B$13*E451,2) | N451: =ROUNDUP((L451+M451-Premissas!$B$5*L451)/(1-Premissas!$B$6-Premissas!$B$7-Premissas!$B$5-Premissas!$B$14),2) | O451: =ROUND(IF(N451<=30000,N451*(1+Premissas!$B$21),N451+Premissas!$B$21*30000*SQRT(N451/30000)),2) | P451: =N451-I451 | Q451: =P451/I451 | R451: =(I451-L451-Premissas!$B$5*(I451-L451)-(Premissas!$B$6+Premissas!$B$7)*I451-M451)/I451 | S451: =ROUND((CEILING((L451*Premissas!$B$19/Premissas!$B$20-97)/100,1)*100+97)*Premissas!$B$20,2)
A452: KIT 11 MOD. 620W + MICROINVERSOR HOYMILES 2,25KW | B452: HOYMILES | C452: Micro | D452: 11 | E452: 6.82 | F452: Microinversor HOYMILES 2,25kW | G452: 3 | H452: Sim | I452: 18739.29 | J452: =(D452*Premissas!$B$24+(2*ROUNDUP(D452/2,0))*Premissas!$B$26+INT((2*ROUNDUP(D452/2,0))/4)*Premissas!$B$27+MOD((2*ROUNDUP(D452/2,0)),4)/2*Premissas!$B$28+2*IF(D452<=19,3*D452,IF(D452<=50,ROUNDUP(2.5*D452,0),2*D452))*Premissas!$B$29+IF(C452="Micro",G452*(Premissas!$B$31+Premissas!$B$32+4*Premissas!$B$30),G452*(INDEX(Premissas!$B$40:$B$71,MATCH(F452,Premissas!$A$40:$A$71,0))+INDEX(Premissas!$C$40:$C$71,MATCH(F452,Premissas!$A$40:$A$71,0))*Premissas!$B$30))) | K452: =IF(J452<Premissas!$B$36,MAX(Premissas!$B$33,J452*Premissas!$B$34),J452*Premissas!$B$35) | L452: =ROUND(J452+K452,2) | M452: =D452*Premissas!$B$8+Premissas!$B$9+Premissas!$B$10+Premissas!$B$11+Premissas!$B$12+ROUND(Premissas!$B$13*E452,2) | N452: =ROUNDUP((L452+M452-Premissas!$B$5*L452)/(1-Premissas!$B$6-Premissas!$B$7-Premissas!$B$5-Premissas!$B$14),2) | O452: =ROUND(IF(N452<=30000,N452*(1+Premissas!$B$21),N452+Premissas!$B$21*30000*SQRT(N452/30000)),2) | P452: =N452-I452 | Q452: =P452/I452 | R452: =(I452-L452-Premissas!$B$5*(I452-L452)-(Premissas!$B$6+Premissas!$B$7)*I452-M452)/I452 | S452: =ROUND((CEILING((L452*Premissas!$B$19/Premissas!$B$20-97)/100,1)*100+97)*Premissas!$B$20,2)
A453: KIT 12 MOD. 620W + MICROINVERSOR HOYMILES 2,25KW | B453: HOYMILES | C453: Micro | D453: 12 | E453: 7.44 | F453: Microinversor HOYMILES 2,25kW | G453: 3 | H453: Sim | I453: 19810.29 | J453: =(D453*Premissas!$B$24+(2*ROUNDUP(D453/2,0))*Premissas!$B$26+INT((2*ROUNDUP(D453/2,0))/4)*Premissas!$B$27+MOD((2*ROUNDUP(D453/2,0)),4)/2*Premissas!$B$28+2*IF(D453<=19,3*D453,IF(D453<=50,ROUNDUP(2.5*D453,0),2*D453))*Premissas!$B$29+IF(C453="Micro",G453*(Premissas!$B$31+Premissas!$B$32+4*Premissas!$B$30),G453*(INDEX(Premissas!$B$40:$B$71,MATCH(F453,Premissas!$A$40:$A$71,0))+INDEX(Premissas!$C$40:$C$71,MATCH(F453,Premissas!$A$40:$A$71,0))*Premissas!$B$30))) | K453: =IF(J453<Premissas!$B$36,MAX(Premissas!$B$33,J453*Premissas!$B$34),J453*Premissas!$B$35) | L453: =ROUND(J453+K453,2) | M453: =D453*Premissas!$B$8+Premissas!$B$9+Premissas!$B$10+Premissas!$B$11+Premissas!$B$12+ROUND(Premissas!$B$13*E453,2) | N453: =ROUNDUP((L453+M453-Premissas!$B$5*L453)/(1-Premissas!$B$6-Premissas!$B$7-Premissas!$B$5-Premissas!$B$14),2) | O453: =ROUND(IF(N453<=30000,N453*(1+Premissas!$B$21),N453+Premissas!$B$21*30000*SQRT(N453/30000)),2) | P453: =N453-I453 | Q453: =P453/I453 | R453: =(I453-L453-Premissas!$B$5*(I453-L453)-(Premissas!$B$6+Premissas!$B$7)*I453-M453)/I453 | S453: =ROUND((CEILING((L453*Premissas!$B$19/Premissas!$B$20-97)/100,1)*100+97)*Premissas!$B$20,2)
A454: KIT 13 MOD. 620W + MICROINVERSOR HOYMILES 2,25KW | B454: HOYMILES | C454: Micro | D454: 13 | E454: 8.06 | F454: Microinversor HOYMILES 2,25kW | G454: 4 | H454: Sim | I454: 22701.99 | J454: =(D454*Premissas!$B$24+(2*ROUNDUP(D454/2,0))*Premissas!$B$26+INT((2*ROUNDUP(D454/2,0))/4)*Premissas!$B$27+MOD((2*ROUNDUP(D454/2,0)),4)/2*Premissas!$B$28+2*IF(D454<=19,3*D454,IF(D454<=50,ROUNDUP(2.5*D454,0),2*D454))*Premissas!$B$29+IF(C454="Micro",G454*(Premissas!$B$31+Premissas!$B$32+4*Premissas!$B$30),G454*(INDEX(Premissas!$B$40:$B$71,MATCH(F454,Premissas!$A$40:$A$71,0))+INDEX(Premissas!$C$40:$C$71,MATCH(F454,Premissas!$A$40:$A$71,0))*Premissas!$B$30))) | K454: =IF(J454<Premissas!$B$36,MAX(Premissas!$B$33,J454*Premissas!$B$34),J454*Premissas!$B$35) | L454: =ROUND(J454+K454,2) | M454: =D454*Premissas!$B$8+Premissas!$B$9+Premissas!$B$10+Premissas!$B$11+Premissas!$B$12+ROUND(Premissas!$B$13*E454,2) | N454: =ROUNDUP((L454+M454-Premissas!$B$5*L454)/(1-Premissas!$B$6-Premissas!$B$7-Premissas!$B$5-Premissas!$B$14),2) | O454: =ROUND(IF(N454<=30000,N454*(1+Premissas!$B$21),N454+Premissas!$B$21*30000*SQRT(N454/30000)),2) | P454: =N454-I454 | Q454: =P454/I454 | R454: =(I454-L454-Premissas!$B$5*(I454-L454)-(Premissas!$B$6+Premissas!$B$7)*I454-M454)/I454 | S454: =ROUND((CEILING((L454*Premissas!$B$19/Premissas!$B$20-97)/100,1)*100+97)*Premissas!$B$20,2)
A455: KIT 14 MOD. 620W + MICROINVERSOR HOYMILES 2,25KW | B455: HOYMILES | C455: Micro | D455: 14 | E455: 8.68 | F455: Microinversor HOYMILES 2,25kW | G455: 4 | H455: Sim | I455: 23772.99 | J455: =(D455*Premissas!$B$24+(2*ROUNDUP(D455/2,0))*Premissas!$B$26+INT((2*ROUNDUP(D455/2,0))/4)*Premissas!$B$27+MOD((2*ROUNDUP(D455/2,0)),4)/2*Premissas!$B$28+2*IF(D455<=19,3*D455,IF(D455<=50,ROUNDUP(2.5*D455,0),2*D455))*Premissas!$B$29+IF(C455="Micro",G455*(Premissas!$B$31+Premissas!$B$32+4*Premissas!$B$30),G455*(INDEX(Premissas!$B$40:$B$71,MATCH(F455,Premissas!$A$40:$A$71,0))+INDEX(Premissas!$C$40:$C$71,MATCH(F455,Premissas!$A$40:$A$71,0))*Premissas!$B$30))) | K455: =IF(J455<Premissas!$B$36,MAX(Premissas!$B$33,J455*Premissas!$B$34),J455*Premissas!$B$35) | L455: =ROUND(J455+K455,2) | M455: =D455*Premissas!$B$8+Premissas!$B$9+Premissas!$B$10+Premissas!$B$11+Premissas!$B$12+ROUND(Premissas!$B$13*E455,2) | N455: =ROUNDUP((L455+M455-Premissas!$B$5*L455)/(1-Premissas!$B$6-Premissas!$B$7-Premissas!$B$5-Premissas!$B$14),2) | O455: =ROUND(IF(N455<=30000,N455*(1+Premissas!$B$21),N455+Premissas!$B$21*30000*SQRT(N455/30000)),2) | P455: =N455-I455 | Q455: =P455/I455 | R455: =(I455-L455-Premissas!$B$5*(I455-L455)-(Premissas!$B$6+Premissas!$B$7)*I455-M455)/I455 | S455: =ROUND((CEILING((L455*Premissas!$B$19/Premissas!$B$20-97)/100,1)*100+97)*Premissas!$B$20,2)
A456: KIT 15 MOD. 620W + MICROINVERSOR HOYMILES 2,25KW | B456: HOYMILES | C456: Micro | D456: 15 | E456: 9.3 | F456: Microinversor HOYMILES 2,25kW | G456: 4 | H456: Sim | I456: 25058.19 | J456: =(D456*Premissas!$B$24+(2*ROUNDUP(D456/2,0))*Premissas!$B$26+INT((2*ROUNDUP(D456/2,0))/4)*Premissas!$B$27+MOD((2*ROUNDUP(D456/2,0)),4)/2*Premissas!$B$28+2*IF(D456<=19,3*D456,IF(D456<=50,ROUNDUP(2.5*D456,0),2*D456))*Premissas!$B$29+IF(C456="Micro",G456*(Premissas!$B$31+Premissas!$B$32+4*Premissas!$B$30),G456*(INDEX(Premissas!$B$40:$B$71,MATCH(F456,Premissas!$A$40:$A$71,0))+INDEX(Premissas!$C$40:$C$71,MATCH(F456,Premissas!$A$40:$A$71,0))*Premissas!$B$30))) | K456: =IF(J456<Premissas!$B$36,MAX(Premissas!$B$33,J456*Premissas!$B$34),J456*Premissas!$B$35) | L456: =ROUND(J456+K456,2) | M456: =D456*Premissas!$B$8+Premissas!$B$9+Premissas!$B$10+Premissas!$B$11+Premissas!$B$12+ROUND(Premissas!$B$13*E456,2) | N456: =ROUNDUP((L456+M456-Premissas!$B$5*L456)/(1-Premissas!$B$6-Premissas!$B$7-Premissas!$B$5-Premissas!$B$14),2) | O456: =ROUND(IF(N456<=30000,N456*(1+Premissas!$B$21),N456+Premissas!$B$21*30000*SQRT(N456/30000)),2) | P456: =N456-I456 | Q456: =P456/I456 | R456: =(I456-L456-Premissas!$B$5*(I456-L456)-(Premissas!$B$6+Premissas!$B$7)*I456-M456)/I456 | S456: =ROUND((CEILING((L456*Premissas!$B$19/Premissas!$B$20-97)/100,1)*100+97)*Premissas!$B$20,2)
... A591: KIT 150 MOD. 620W + MICROINVERSOR HOYMILES 2,25KW | B591: HOYMILES | C591: Micro | D591: 150 | E591: 93 | F591: Microinversor HOYMILES 2,25kW | G591: 38 | H591: Sim | I591: 244613.19 | J591: =(D591*Premissas!$B$24+(2*ROUNDUP(D591/2,0))*Premissas!$B$26+INT((2*ROUNDUP(D591/2,0))/4)*Premissas!$B$27+MOD((2*ROUNDUP(D591/2,0)),4)/2*Premissas!$B$28+2*IF(D591<=19,3*D591,IF(D591<=50,ROUNDUP(2.5*D591,0),2*D591))*Premissas!$B$29+IF(C591="Micro",G591*(Premissas!$B$31+Premissas!$B$32+4*Premissas!$B$30),G591*(INDEX(Premissas!$B$40:$B$71,MATCH(F591,Premissas!$A$40:$A$71,0))+INDEX(Premissas!$C$40:$C$71,MATCH(F591,Premissas!$A$40:$A$71,0))*Premissas!$B$30))) | K591: =IF(J591<Premissas!$B$36,MAX(Premissas!$B$33,J591*Premissas!$B$34),J591*Premissas!$B$35) | L591: =ROUND(J591+K591,2) | M591: =D591*Premissas!$B$8+Premissas!$B$9+Premissas!$B$10+Premissas!$B$11+Premissas!$B$12+ROUND(Premissas!$B$13*E591,2) | N591: =ROUNDUP((L591+M591-Premissas!$B$5*L591)/(1-Premissas!$B$6-Premissas!$B$7-Premissas!$B$5-Premissas!$B$14),2) | O591: =ROUND(IF(N591<=30000,N591*(1+Premissas!$B$21),N591+Premissas!$B$21*30000*SQRT(N591/30000)),2) | P591: =N591-I591 | Q591: =P591/I591 | R591: =(I591-L591-Premissas!$B$5*(I591-L591)-(Premissas!$B$6+Premissas!$B$7)*I591-M591)/I591 | S591: =ROUND((CEILING((L591*Premissas!$B$19/Premissas!$B$20-97)/100,1)*100+97)*Premissas!$B$20,2)

Sheet Cotacao
A1: Cotação de distribuidora: markup × custos
A2: Preencha em amarelo. Mesma conta que a plataforma faz na cotação da Belenus quando a unidade está no modo custos.
A4: Distribuidora | B4: Descrição | C4: Tipo (Inversor/Micro) | D4: Módulos | E4: kWp | F4: Custo do kit c/ frete | G4: Preço markup | H4: Custos fixos da obra | I4: Preço por custos | J4: "De" por custos | K4: Diferença (%)
A5: Belenus | B5: KIT 6 MOD. 580W + INV. GROWATT 3KW (cotação real 08/10) | C5: Inversor | D5: 6 | E5: 3.48 | F5: 6025.04 | G5: =IF(OR(D5="",E5="",F5=""),"",ROUND((CEILING((F5*IF(C5="Micro",Premissas!$B$19,Premissas!$B$17)/IF(C5="Micro",Premissas!$B$20,Premissas!$B$18)-97)/100,1)*100+97)*IF(C5="Micro",Premissas!$B$20,Premissas!$B$18),2)) | H5: =IF(OR(D5="",E5="",F5=""),"",D5*Premissas!$B$8+Premissas!$B$9+Premissas!$B$10+Premissas!$B$11+Premissas!$B$12+ROUND(Premissas!$B$13*E5,2)) | I5: =IF(OR(D5="",E5="",F5=""),"",ROUNDUP((F5+H5-Premissas!$B$5*F5)/(1-Premissas!$B$6-Premissas!$B$7-Premissas!$B$5-Premissas!$B$14),2)) | J5: =IF(I5="","",ROUND(IF(I5<=30000,I5*(1+Premissas!$B$21),I5+Premissas!$B$21*30000*SQRT(I5/30000)),2)) | K5: =IF(I5="","",I5/G5-1)
A6: Belenus | B6: KIT 6 MOD. 580W + INV. SOLIS 3KW (cotação real 08/10) | C6: Inversor | D6: 6 | E6: 3.48 | F6: 6817.13 | G6: =IF(OR(D6="",E6="",F6=""),"",ROUND((CEILING((F6*IF(C6="Micro",Premissas!$B$19,Premissas!$B$17)/IF(C6="Micro",Premissas!$B$20,Premissas!$B$18)-97)/100,1)*100+97)*IF(C6="Micro",Premissas!$B$20,Premissas!$B$18),2)) | H6: =IF(OR(D6="",E6="",F6=""),"",D6*Premissas!$B$8+Premissas!$B$9+Premissas!$B$10+Premissas!$B$11+Premissas!$B$12+ROUND(Premissas!$B$13*E6,2)) | I6: =IF(OR(D6="",E6="",F6=""),"",ROUNDUP((F6+H6-Premissas!$B$5*F6)/(1-Premissas!$B$6-Premissas!$B$7-Premissas!$B$5-Premissas!$B$14),2)) | J6: =IF(I6="","",ROUND(IF(I6<=30000,I6*(1+Premissas!$B$21),I6+Premissas!$B$21*30000*SQRT(I6/30000)),2)) | K6: =IF(I6="","",I6/G6-1)
A7: Helte | B7: KIT 9 MOD. 620W + INV. SOFAR 5KW (cotação real 08/10) | C7: Inversor | D7: 9 | E7: 5.58 | F7: 7965.87 | G7: =IF(OR(D7="",E7="",F7=""),"",ROUND((CEILING((F7*IF(C7="Micro",Premissas!$B$19,Premissas!$B$17)/IF(C7="Micro",Premissas!$B$20,Premissas!$B$18)-97)/100,1)*100+97)*IF(C7="Micro",Premissas!$B$20,Premissas!$B$18),2)) | H7: =IF(OR(D7="",E7="",F7=""),"",D7*Premissas!$B$8+Premissas!$B$9+Premissas!$B$10+Premissas!$B$11+Premissas!$B$12+ROUND(Premissas!$B$13*E7,2)) | I7: =IF(OR(D7="",E7="",F7=""),"",ROUNDUP((F7+H7-Premissas!$B$5*F7)/(1-Premissas!$B$6-Premissas!$B$7-Premissas!$B$5-Premissas!$B$14),2)) | J7: =IF(I7="","",ROUND(IF(I7<=30000,I7*(1+Premissas!$B$21),I7+Premissas!$B$21*30000*SQRT(I7/30000)),2)) | K7: =IF(I7="","",I7/G7-1)
